<?xml version="1.0"?>
<robot name="mini_cheetah"
  xmlns:xacro="http://www.ros.org/wiki/xacro">

  <!-- LEG MACRO -->
  <xacro:macro name="abad" params="prefix offset_x offset_y rotate_y rotate_z rotate_y_upper rotate_y_lower">
    <!-- LINK ABAD -->
    <link name="link_${prefix}_abad">
      <pose> 0 0 0 0 0 0</pose>

      <inertial>
        <mass value="5"/>
        <origin rpy="0 0 0" xyz="0 0 0.1"/>
        <inertia ixx="0.03" ixy="0" ixz="0" iyy="0" iyz="0" izz="0"/>
      </inertial>

      <visual>
        <geometry>
          <mesh filename="package://mit_cheetah_gazebo/description/models/mini_cheetah/mini_abad.obj"/>
        </geometry>
        <!-- <material name="Cyan">
          <color rgba="0 0.0 1.0 1.0"/>
        </material> -->
      </visual>

      <collision>
        <geometry>
          <mesh filename="package://mit_cheetah_gazebo/description/models/mini_cheetah/mini_abad.obj"/>
        </geometry>
      </collision>
    </link>
    <!--  -->

    <!-- JOINT ABAD TO BODY -->
    <joint name="${prefix}_abad_to_body" type="revolute">
      <parent link="link_body"/>
      <child link="link_${prefix}_abad"/>
      <axis xyz="0 1 0" />
      <origin rpy="0 ${3.14159 * rotate_y} ${1.5708 * rotate_z}" xyz="${0.139 * offset_x} ${0.05 * offset_y} 0"/>
      <limit effort="1000.0" lower="-1.57079" upper="1.57079" velocity="1" />
    </joint>
    <!--  -->

    <!-- LINK UPPER -->
    <link name="link_${prefix}_upper">
      <pose> 0 0 0 0 0 0</pose>

      <inertial>
        <mass value="5"/>
        <origin rpy="0 0 0" xyz="0 0 0.1"/>
        <inertia ixx="0.03" ixy="0" ixz="0" iyy="0" iyz="0" izz="0"/>
      </inertial>

      <visual>
        <geometry>
          <mesh filename="package://mit_cheetah_gazebo/description/models/mini_cheetah/mini_upper_link.obj"/>
        </geometry>
        <!-- <material name="Cyan">
          <color rgba="0 0.0 1.0 1.0"/>
        </material> -->
      </visual>

      <collision>
        <geometry>
          <mesh filename="package://mit_cheetah_gazebo/description/models/mini_cheetah/mini_upper_link.obj"/>
        </geometry>
      </collision>
    </link>
    <!--  -->

    <!-- JOINT UPPER TO ABAD -->
    <joint name="${prefix}_upper_to_abad" type="revolute">
      <parent link="link_${prefix}_abad"/>
      <child link="link_${prefix}_upper"/>
      <axis xyz="0 1 0" />
      <origin rpy="3.14159 ${3.14159 * rotate_y_upper} 1.5708" xyz="-0.0613 0.0575 0"/>
      <limit effort="1000.0" lower="-1.57079" upper="1.57079" velocity="1" />
    </joint>
    <!--  -->

    <!-- LINK LOWER -->
    <link name="link_${prefix}_lower">
      <pose> 0 0 0 0 0 0</pose>

      <inertial>
        <mass value="5"/>
        <origin rpy="0 0 0" xyz="0 0 0.1"/>
        <inertia ixx="0.03" ixy="0" ixz="0" iyy="0" iyz="0" izz="0"/>
      </inertial>

      <visual>
        <geometry>
          <mesh filename="package://mit_cheetah_gazebo/description/models/mini_cheetah/mini_lower_link.obj"/>
        </geometry>
        <!-- <material name="Cyan">
          <color rgba="0 0.0 1.0 1.0"/>
        </material> -->
      </visual>

      <collision>
        <geometry>
          <mesh filename="package://mit_cheetah_gazebo/description/models/mini_cheetah/mini_lower_link.obj"/>
        </geometry>
      </collision>
    </link>
    <!--  -->

    <!-- JOINT LOWER TO UPPER -->
    <joint name="${prefix}_lower_to_upper" type="revolute">
      <parent link="link_${prefix}_upper"/>
      <child link="link_${prefix}_lower"/>
      <axis xyz="0 1 0" />
      <origin rpy="0 ${3.14159 * rotate_y_lower} 0" xyz="-0.20835 -0.0011 0"/>
      <limit effort="1000.0" lower="-1.57079" upper="1.57079" velocity="1" />
    </joint>
    <!--  -->
  </xacro:macro>
  <!--  -->

  <!--################################## LINKS ##################################-->
  <!-- LINK ROOT -->
  <link name="link_root">
    <pose> 0 0 0 0 0 0</pose>
  </link>
  <!--  -->

  <!-- LINK BODY -->
  <link name="link_body">
    <pose> 0 0 0 0 0 0</pose>

    <inertial>
      <mass value="5"/>
      <origin rpy="0 0 0" xyz="0 0 0.1"/>
      <inertia ixx="0.03" ixy="0" ixz="0" iyy="0" iyz="0" izz="0"/>
    </inertial>

    <collision>
      <geometry>
        <mesh filename="package://mit_cheetah_gazebo/description/models/mini_cheetah/mini_body.obj"/>
      </geometry>
    </collision>

    <visual>
      <origin rpy="0 0 0" xyz="0 0 0"/>
      <geometry>
        <mesh filename="package://mit_cheetah_gazebo/description/models/mini_cheetah/mini_body.obj"/>
      </geometry>
    </visual>
  </link>
  <!--  -->

  <!-- start from lf 4 legs -->
  <xacro:abad prefix="fl" offset_x="1" offset_y="1" rotate_y="0" rotate_z="-1" rotate_y_upper="0" rotate_y_lower="0"/>
  <xacro:abad prefix="fr" offset_x="1" offset_y="-1" rotate_y="1" rotate_z="-1" rotate_y_upper="0" rotate_y_lower="1"/>
  <xacro:abad prefix="bl" offset_x="-1" offset_y="1" rotate_y="1" rotate_z="1" rotate_y_upper="1" rotate_y_lower="0"/>
  <xacro:abad prefix="br" offset_x="-1" offset_y="-1" rotate_y="0" rotate_z="1" rotate_y_upper="1" rotate_y_lower="1"/>
  <!--############################################################################-->

  <!--################################## JOINTS ##################################-->
  <!-- JOINT BODY TO ROOT -->
  <joint name="root_to_body" type="fixed">
    <parent link="link_root"/>
    <child link="link_body"/>
    <origin rpy="0 0 0" xyz="0 0 0"/>
  </joint>
  <!--  -->
  <!--############################################################################-->

  <!--################################## PLUGINS ##################################-->

  <gazebo>
    <plugin name = "gazebo_ros_control" filename = "libgazebo_ros_control.so">
      <robotNamespace>/mini_cheetah</robotNamespace>
    </plugin>
  </gazebo>

  <!-- servo 0 -->
  <transmission name = "joint_0">
    <type>transmission_interface/SimpleTransmision</type>
    <actuator name = "joint_0">
      <mechanicalReduction>1</mechanicalReduction>
    </actuator>
    <joint name = "fr_abad_to_body">
      <hardwareInterface>hardware_interface/EffortJointInterface</hardwareInterface>
    </joint>
  </transmission>
  <!--  -->

  <!-- servo 1 -->
  <transmission name = "joint_1">
    <type>transmission_interface/SimpleTransmision</type>
    <actuator name = "joint_1">
      <mechanicalReduction>1</mechanicalReduction>
    </actuator>
    <joint name = "fr_upper_to_abad">
      <hardwareInterface>hardware_interface/EffortJointInterface</hardwareInterface>
    </joint>
  </transmission>
  <!--  -->

</robot>
